<?xml version="1.0" ?>
<sdf version="1.10">
  <model name="teleh4z" canonical_link="base_link">
    <static>false</static>
    <self_collide>false</self_collide>
    <allow_auto_disable>false</allow_auto_disable>

    <link name="base_link">
      <gravity>1</gravity>
      <velocity_decay>
        <linear>0.01</linear>
        <angular>0.01</angular>
      </velocity_decay>
      <pose>0 0 0 0 0 0</pose>

      <inertial>
        <mass>2.25</mass>
        <pose>0 0 -0.015 0 0 0</pose>
        <inertia>
          <ixx>0.00166875</ixx>
          <ixy>0</ixy>
          <ixz>0</ixz>
          <iyy>0.01734375</iyy>
          <iyz>0</iyz>
          <izz>0.018075</izz>
        </inertia>
        <!-- HybridHydrodynamics v2 当前由插件侧附加质量主导。
             下面这段 <fluid_added_mass> 必须保持注释，否则会与插件内
             的 -M_A * nu_dot_r / C_A(nu_r)nu_r 双重叠加。 -->
        <!-- <fluid_added_mass>
          <xx>2.4</xx>
          <yy>5.2</yy>
          <zz>2.1</zz>
          <pp>0.08</pp>
          <qq>0.24</qq>
          <rr>0.32</rr>
        </fluid_added_mass> -->
      </inertial>

      <visual name="body_main_visual">
        <pose>0 0 0 0 0 0</pose>
        <geometry>
          <mesh>
            <uri>meshes/body_main_colored.dae</uri>
          </mesh>
        </geometry>
      </visual>

      <collision name="base_buoyancy_collision">
        <pose>0 0 -0.03 0 0 0</pose>
        <geometry>
          <box>
            <size>0.30 0.08 0.05</size>
          </box>
        </geometry>
        <surface>
          <contact>
            <ode>
              <min_depth>0.001</min_depth>
              <max_vel>0.15</max_vel>
              <kp>100000.0</kp>
              <kd>100.0</kd>
            </ode>
          </contact>
          <friction>
            <ode>
              <mu>0.5</mu>
              <mu2>0.5</mu2>
            </ode>
          </friction>
        </surface>
      </collision>

      <sensor name="imu_sensor" type="imu">
        <always_on>1</always_on>
        <update_rate>250</update_rate>
        <visualize>true</visualize>
        <imu>
          <angular_velocity>
            <x><noise type="gaussian"><mean>0</mean><stddev>2e-4</stddev></noise></x>
            <y><noise type="gaussian"><mean>0</mean><stddev>2e-4</stddev></noise></y>
            <z><noise type="gaussian"><mean>0</mean><stddev>2e-4</stddev></noise></z>
          </angular_velocity>
          <linear_acceleration>
            <x><noise type="gaussian"><mean>0</mean><stddev>1.7e-2</stddev></noise></x>
            <y><noise type="gaussian"><mean>0</mean><stddev>1.7e-2</stddev></noise></y>
            <z><noise type="gaussian"><mean>0</mean><stddev>1.7e-2</stddev></noise></z>
          </linear_acceleration>
        </imu>
      </sensor>

      <sensor name="magnetometer_sensor" type="magnetometer">
        <always_on>1</always_on>
        <update_rate>100</update_rate>
        <magnetometer>
          <x><noise type="gaussian"><stddev>0.0001</stddev></noise></x>
          <y><noise type="gaussian"><stddev>0.0001</stddev></noise></y>
          <z><noise type="gaussian"><stddev>0.0001</stddev></noise></z>
        </magnetometer>
      </sensor>

      <sensor name="air_pressure_sensor" type="air_pressure">
        <always_on>1</always_on>
        <update_rate>50</update_rate>
        <air_pressure>
          <pressure>
            <noise type="gaussian"><mean>0</mean><stddev>0.01</stddev></noise>
          </pressure>
        </air_pressure>
      </sensor>

      <sensor name="navsat_sensor" type="navsat">
        <always_on>1</always_on>
        <update_rate>30</update_rate>
      </sensor>
    </link>

    <link name="buoyancy_shell_link">
      <pose relative_to="base_link">0 0 0 0 0 0</pose>
      <inertial>
        <mass>0.5</mass>
        <inertia>
          <ixx>0.0011360133</ixx>
          <iyy>0.0020696800</iyy>
          <izz>0.0027333333</izz>
          <ixy>0</ixy>
          <ixz>0</ixz>
          <iyz>0</iyz>
        </inertia>
      </inertial>

      <visual name="buoyancy_shell_visual">
        <pose>0 0 0 0 0 0</pose>
        <geometry>
          <mesh>
            <uri>meshes/buoyancy_shell_colored.dae</uri>
          </mesh>
        </geometry>
      </visual>

      <collision name="shell_buoyancy_collision">
        <pose>0 0 0.05 0 0 0</pose>
        <geometry>
          <box>
            <size>0.24 0.16 0.0408854167</size>
          </box>
        </geometry>
      </collision>
    </link>

    <joint name="buoyancy_shell_joint" type="fixed">
      <parent>base_link</parent>
      <child>buoyancy_shell_link</child>
    </joint>

    <link name="camera_link">
      <pose relative_to="base_link">0.144 0 -0.0148 0 0 0</pose>
      <inertial>
        <mass>1e-4</mass>
        <inertia>
          <ixx>1e-8</ixx>
          <iyy>1e-8</iyy>
          <izz>1e-8</izz>
          <ixy>0</ixy>
          <ixz>0</ixz>
          <iyz>0</iyz>
        </inertia>
      </inertial>

      <visual name="camera_visual">
        <pose>0 0 0 0 0 0</pose>
        <geometry>
          <mesh>
            <uri>meshes/camera.stl</uri>
          </mesh>
        </geometry>
        <material>
          <ambient>0.05 0.05 0.05 1</ambient>
          <diffuse>0.14 0.14 0.14 1</diffuse>
          <specular>0.92 0.92 0.92 1</specular>
          <emissive>0.01 0.01 0.01 1</emissive>
        </material>
      </visual>

      <sensor name="front_camera" type="camera">
        <pose>0 0 0 0 0 0</pose>
        <camera>
          <horizontal_fov>1.74</horizontal_fov>
          <image>
            <format>R8G8B8</format>
            <width>1280</width>
            <height>960</height>
          </image>
          <clip>
            <near>0.1</near>
            <far>3000</far>
          </clip>
        </camera>
        <always_on>1</always_on>
        <update_rate>30</update_rate>
        <visualize>true</visualize>
        <topic>camera</topic>
      </sensor>
    </link>

    <joint name="camera_joint" type="fixed">
      <parent>base_link</parent>
      <child>camera_link</child>
    </joint>

    <link name="waterprop_mount_left_link">
      <pose relative_to="base_link">-0.155 0.036 -0.007866 0 0 0</pose>
      <inertial>
        <mass>1e-4</mass>
        <inertia>
          <ixx>1e-8</ixx>
          <iyy>1e-8</iyy>
          <izz>1e-8</izz>
          <ixy>0</ixy>
          <ixz>0</ixz>
          <iyz>0</iyz>
        </inertia>
      </inertial>
      <visual name="waterprop_mount_left_visual">
        <geometry>
          <mesh>
            <uri>meshes/waterprop_mont.stl</uri>
          </mesh>
        </geometry>
        <material>
          <ambient>0.03 0.03 0.03 1</ambient>
          <diffuse>0.07 0.07 0.07 1</diffuse>
          <specular>0.45 0.45 0.45 1</specular>
        </material>
      </visual>
    </link>

    <joint name="waterprop_mount_left_joint" type="fixed">
      <parent>base_link</parent>
      <child>waterprop_mount_left_link</child>
    </joint>

    <link name="waterprop_mount_right_link">
      <pose relative_to="base_link">-0.155 -0.036 -0.007866 0 0 0</pose>
      <inertial>
        <mass>1e-4</mass>
        <inertia>
          <ixx>1e-8</ixx>
          <iyy>1e-8</iyy>
          <izz>1e-8</izz>
          <ixy>0</ixy>
          <ixz>0</ixz>
          <iyz>0</iyz>
        </inertia>
      </inertial>
      <visual name="waterprop_mount_right_visual">
        <geometry>
          <mesh>
            <uri>meshes/waterprop_mont.stl</uri>
          </mesh>
        </geometry>
        <material>
          <ambient>0.03 0.03 0.03 1</ambient>
          <diffuse>0.07 0.07 0.07 1</diffuse>
          <specular>0.45 0.45 0.45 1</specular>
        </material>
      </visual>
    </link>

    <joint name="waterprop_mount_right_joint" type="fixed">
      <parent>base_link</parent>
      <child>waterprop_mount_right_link</child>
    </joint>

    <link name="waterprop_mount_front_link">
      <pose relative_to="base_link">0.1139 0 0.04 0 1.57079632679 0</pose>
      <inertial>
        <mass>1e-4</mass>
        <inertia>
          <ixx>1e-8</ixx>
          <iyy>1e-8</iyy>
          <izz>1e-8</izz>
          <ixy>0</ixy>
          <ixz>0</ixz>
          <iyz>0</iyz>
        </inertia>
      </inertial>
      <visual name="waterprop_mount_front_visual">
        <geometry>
          <mesh>
            <uri>meshes/waterprop_mont.stl</uri>
          </mesh>
        </geometry>
        <material>
          <ambient>0.03 0.03 0.03 1</ambient>
          <diffuse>0.07 0.07 0.07 1</diffuse>
          <specular>0.45 0.45 0.45 1</specular>
        </material>
      </visual>
    </link>

    <joint name="waterprop_mount_front_joint" type="fixed">
      <parent>base_link</parent>
      <child>waterprop_mount_front_link</child>
    </joint>

    <link name="waterprop_mount_back_link">
      <pose relative_to="base_link">-0.10643 0 0.04 0 1.57079632679 0</pose>
      <inertial>
        <mass>1e-4</mass>
        <inertia>
          <ixx>1e-8</ixx>
          <iyy>1e-8</iyy>
          <izz>1e-8</izz>
          <ixy>0</ixy>
          <ixz>0</ixz>
          <iyz>0</iyz>
        </inertia>
      </inertial>
      <visual name="waterprop_mount_back_visual">
        <geometry>
          <mesh>
            <uri>meshes/waterprop_mont.stl</uri>
          </mesh>
        </geometry>
        <material>
          <ambient>0.03 0.03 0.03 1</ambient>
          <diffuse>0.07 0.07 0.07 1</diffuse>
          <specular>0.45 0.45 0.45 1</specular>
        </material>
      </visual>
    </link>

    <joint name="waterprop_mount_back_joint" type="fixed">
      <parent>base_link</parent>
      <child>waterprop_mount_back_link</child>
    </joint>

    <link name="arm_right_link">
      <pose relative_to="base_link">0.0219 -0.0445 0.0705 0 0 0</pose>
      <inertial>
        <mass>1e-4</mass>
        <inertia>
          <ixx>1e-8</ixx>
          <iyy>1e-8</iyy>
          <izz>1e-8</izz>
          <ixy>0</ixy>
          <ixz>0</ixz>
          <iyz>0</iyz>
        </inertia>
      </inertial>

      <visual name="arm_right_visual">
        <geometry>
          <mesh>
            <uri>meshes/arm_right_colored.dae</uri>
          </mesh>
        </geometry>
      </visual>

    </link>

    <joint name="arm_right_joint" type="revolute">
      <parent>base_link</parent>
      <child>arm_right_link</child>
      <axis>
        <xyz>-1 0 0</xyz>
        <limit>
          <lower>0.0</lower>
          <upper>1.57079632679</upper>
          <effort>50</effort>
          <velocity>5</velocity>
        </limit>
        <dynamics>
          <damping>0.05</damping>
          <friction>0.0</friction>
        </dynamics>
      </axis>
    </joint>

    <link name="arm_left_link">
      <pose relative_to="base_link">0.0219 0.0445 0.0705 0 0 0</pose>
      <inertial>
        <mass>1e-4</mass>
        <inertia>
          <ixx>1e-8</ixx>
          <iyy>1e-8</iyy>
          <izz>1e-8</izz>
          <ixy>0</ixy>
          <ixz>0</ixz>
          <iyz>0</iyz>
        </inertia>
      </inertial>

      <visual name="arm_left_visual">
        <geometry>
          <mesh>
            <uri>meshes/arm_left_colored.dae</uri>
          </mesh>
        </geometry>
      </visual>

    </link>

    <joint name="arm_left_joint" type="revolute">
      <parent>base_link</parent>
      <child>arm_left_link</child>
      <axis>
        <xyz>1 0 0</xyz>
        <limit>
          <lower>0.0</lower>
          <upper>1.57079632679</upper>
          <effort>50</effort>
          <velocity>5</velocity>
        </limit>
        <dynamics>
          <damping>0.05</damping>
          <friction>0.0</friction>
        </dynamics>
      </axis>
    </joint>

    <link name="airprop_rightfront_link">
      <pose relative_to="arm_right_link">0.0781 0.0045 -0.0838 1.57079632679 0 0</pose>
      <inertial>
        <mass>1e-4</mass>
        <inertia>
          <ixx>1e-8</ixx>
          <iyy>1e-8</iyy>
          <izz>1e-8</izz>
          <ixy>0</ixy>
          <ixz>0</ixz>
          <iyz>0</iyz>
        </inertia>
      </inertial>
      <visual name="airprop_rightfront_visual">
        <pose>0 0 0 -1.57079632679 0 0</pose>
        <geometry>
          <mesh>
            <uri>meshes/airprop_rightfront.stl</uri>
          </mesh>
        </geometry>
        <material>
          <ambient>0.18 0.01 0.01 1</ambient>
          <diffuse>0.42 0.03 0.03 1</diffuse>
          <specular>0.95 0.95 0.95 1</specular>
          <emissive>0.02 0.00 0.00 1</emissive>
        </material>
      </visual>
    </link>

    <joint name="airprop_rightfront_joint" type="revolute">
      <parent>arm_right_link</parent>
      <child>airprop_rightfront_link</child>
      <axis>
        <xyz>0 0 1</xyz>
        <limit>
          <lower>-1000000</lower>
          <upper>1000000</upper>
          <effort>10</effort>
          <velocity>1000</velocity>
        </limit>
        <dynamics>
          <damping>0.001</damping>
          <friction>0.0</friction>
        </dynamics>
      </axis>
    </joint>

    <link name="airprop_rightback_link">
      <pose relative_to="arm_right_link">-0.1139 0.0045 -0.0838 1.57079632679 0 0</pose>
      <inertial>
        <mass>1e-4</mass>
        <inertia>
          <ixx>1e-8</ixx>
          <iyy>1e-8</iyy>
          <izz>1e-8</izz>
          <ixy>0</ixy>
          <ixz>0</ixz>
          <iyz>0</iyz>
        </inertia>
      </inertial>
      <visual name="airprop_rightback_visual">
        <pose>0 0 0 -1.57079632679 0 0</pose>
        <geometry>
          <mesh>
            <uri>meshes/airprop_rightback.stl</uri>
          </mesh>
        </geometry>
        <material>
          <ambient>0.18 0.01 0.01 1</ambient>
          <diffuse>0.42 0.03 0.03 1</diffuse>
          <specular>0.95 0.95 0.95 1</specular>
          <emissive>0.02 0.00 0.00 1</emissive>
        </material>
      </visual>
    </link>

    <joint name="airprop_rightback_joint" type="revolute">
      <parent>arm_right_link</parent>
      <child>airprop_rightback_link</child>
      <axis>
        <xyz>0 0 1</xyz>
        <limit>
          <lower>-1000000</lower>
          <upper>1000000</upper>
          <effort>10</effort>
          <velocity>1000</velocity>
        </limit>
        <dynamics>
          <damping>0.001</damping>
          <friction>0.0</friction>
        </dynamics>
      </axis>
    </joint>

    <link name="airprop_leftfront_link">
      <pose relative_to="arm_left_link">0.0781 -0.0045 -0.0838 -1.57079632679 0 0</pose>
      <inertial>
        <mass>1e-4</mass>
        <inertia>
          <ixx>1e-8</ixx>
          <iyy>1e-8</iyy>
          <izz>1e-8</izz>
          <ixy>0</ixy>
          <ixz>0</ixz>
          <iyz>0</iyz>
        </inertia>
      </inertial>
      <visual name="airprop_leftfront_visual">
        <pose>0 0 0 1.57079632679 0 0</pose>
        <geometry>
          <mesh>
            <uri>meshes/airprop_leftfront.stl</uri>
          </mesh>
        </geometry>
        <material>
          <ambient>0.01 0.04 0.18 1</ambient>
          <diffuse>0.03 0.12 0.42 1</diffuse>
          <specular>0.95 0.95 0.95 1</specular>
          <emissive>0.00 0.00 0.02 1</emissive>
        </material>
      </visual>
    </link>

    <joint name="airprop_leftfront_joint" type="revolute">
      <parent>arm_left_link</parent>
      <child>airprop_leftfront_link</child>
      <axis>
        <xyz>0 0 1</xyz>
        <limit>
          <lower>-1000000</lower>
          <upper>1000000</upper>
          <effort>10</effort>
          <velocity>1000</velocity>
        </limit>
        <dynamics>
          <damping>0.001</damping>
          <friction>0.0</friction>
        </dynamics>
      </axis>
    </joint>

    <link name="airprop_leftback_link">
      <pose relative_to="arm_left_link">-0.1139 -0.0045 -0.0838 -1.57079632679 0 0</pose>
      <inertial>
        <mass>1e-4</mass>
        <inertia>
          <ixx>1e-8</ixx>
          <iyy>1e-8</iyy>
          <izz>1e-8</izz>
          <ixy>0</ixy>
          <ixz>0</ixz>
          <iyz>0</iyz>
        </inertia>
      </inertial>
      <visual name="airprop_leftback_visual">
        <pose>0 0 0 1.57079632679 0 0</pose>
        <geometry>
          <mesh>
            <uri>meshes/airprop_leftback.stl</uri>
          </mesh>
        </geometry>
        <material>
          <ambient>0.01 0.04 0.18 1</ambient>
          <diffuse>0.03 0.12 0.42 1</diffuse>
          <specular>0.95 0.95 0.95 1</specular>
          <emissive>0.00 0.00 0.02 1</emissive>
        </material>
      </visual>
    </link>

    <joint name="airprop_leftback_joint" type="revolute">
      <parent>arm_left_link</parent>
      <child>airprop_leftback_link</child>
      <axis>
        <xyz>0 0 1</xyz>
        <limit>
          <lower>-1000000</lower>
          <upper>1000000</upper>
          <effort>10</effort>
          <velocity>1000</velocity>
        </limit>
        <dynamics>
          <damping>0.001</damping>
          <friction>0.0</friction>
        </dynamics>
      </axis>
    </joint>

    <link name="waterprop_left_link">
      <pose relative_to="base_link">-0.155 0.036 -0.007866 0 0 0</pose>
      <inertial>
        <mass>1e-4</mass>
        <inertia>
          <ixx>1e-8</ixx>
          <iyy>1e-8</iyy>
          <izz>1e-8</izz>
          <ixy>0</ixy>
          <ixz>0</ixz>
          <iyz>0</iyz>
        </inertia>
      </inertial>
      <visual name="waterprop_left_visual">
        <geometry>
          <mesh>
            <uri>meshes/waterprop.stl</uri>
          </mesh>
        </geometry>
        <material>
          <ambient>0.015 0.015 0.015 1</ambient>
          <diffuse>0.035 0.035 0.035 1</diffuse>
          <specular>0.98 0.98 0.98 1</specular>
          <emissive>0.005 0.005 0.005 1</emissive>
        </material>
      </visual>
    </link>

    <joint name="waterprop_left_joint" type="revolute">
      <parent>base_link</parent>
      <child>waterprop_left_link</child>
      <axis>
        <xyz>1 0 0</xyz>
        <limit>
          <lower>-1000000</lower>
          <upper>1000000</upper>
          <effort>10</effort>
          <velocity>1000</velocity>
        </limit>
        <dynamics>
          <damping>0.001</damping>
          <friction>0.0</friction>
        </dynamics>
      </axis>
    </joint>

    <link name="waterprop_right_link">
      <pose relative_to="base_link">-0.155 -0.036 -0.007866 0 0 0</pose>
      <inertial>
        <mass>1e-4</mass>
        <inertia>
          <ixx>1e-8</ixx>
          <iyy>1e-8</iyy>
          <izz>1e-8</izz>
          <ixy>0</ixy>
          <ixz>0</ixz>
          <iyz>0</iyz>
        </inertia>
      </inertial>
      <visual name="waterprop_right_visual">
        <geometry>
          <mesh>
            <uri>meshes/waterprop.stl</uri>
          </mesh>
        </geometry>
        <material>
          <ambient>0.015 0.015 0.015 1</ambient>
          <diffuse>0.035 0.035 0.035 1</diffuse>
          <specular>0.98 0.98 0.98 1</specular>
          <emissive>0.005 0.005 0.005 1</emissive>
        </material>
      </visual>
    </link>

    <joint name="waterprop_right_joint" type="revolute">
      <parent>base_link</parent>
      <child>waterprop_right_link</child>
      <axis>
        <xyz>1 0 0</xyz>
        <limit>
          <lower>-1000000</lower>
          <upper>1000000</upper>
          <effort>10</effort>
          <velocity>1000</velocity>
        </limit>
        <dynamics>
          <damping>0.001</damping>
          <friction>0.0</friction>
        </dynamics>
      </axis>
    </joint>

    <link name="waterprop_front_link">
      <pose relative_to="base_link">0.1139 0 0.04 0 1.57079632679 0</pose>
      <inertial>
        <mass>1e-4</mass>
        <inertia>
          <ixx>1e-8</ixx>
          <iyy>1e-8</iyy>
          <izz>1e-8</izz>
          <ixy>0</ixy>
          <ixz>0</ixz>
          <iyz>0</iyz>
        </inertia>
      </inertial>
      <visual name="waterprop_front_visual">
        <geometry>
          <mesh>
            <uri>meshes/waterprop.stl</uri>
          </mesh>
        </geometry>
        <material>
          <ambient>0.015 0.015 0.015 1</ambient>
          <diffuse>0.035 0.035 0.035 1</diffuse>
          <specular>0.98 0.98 0.98 1</specular>
          <emissive>0.005 0.005 0.005 1</emissive>
        </material>
      </visual>
    </link>

    <joint name="waterprop_front_joint" type="revolute">
      <parent>base_link</parent>
      <child>waterprop_front_link</child>
      <axis>
        <xyz>1 0 0</xyz>
        <limit>
          <lower>-1000000</lower>
          <upper>1000000</upper>
          <effort>10</effort>
          <velocity>1000</velocity>
        </limit>
        <dynamics>
          <damping>0.001</damping>
          <friction>0.0</friction>
        </dynamics>
      </axis>
    </joint>

    <link name="waterprop_back_link">
      <pose relative_to="base_link">-0.10643 0 0.04 0 1.57079632679 0</pose>
      <inertial>
        <mass>1e-4</mass>
        <inertia>
          <ixx>1e-8</ixx>
          <iyy>1e-8</iyy>
          <izz>1e-8</izz>
          <ixy>0</ixy>
          <ixz>0</ixz>
          <iyz>0</iyz>
        </inertia>
      </inertial>
      <visual name="waterprop_back_visual">
        <geometry>
          <mesh>
            <uri>meshes/waterprop.stl</uri>
          </mesh>
        </geometry>
        <material>
          <ambient>0.015 0.015 0.015 1</ambient>
          <diffuse>0.035 0.035 0.035 1</diffuse>
          <specular>0.98 0.98 0.98 1</specular>
          <emissive>0.005 0.005 0.005 1</emissive>
        </material>
      </visual>
    </link>

    <joint name="waterprop_back_joint" type="revolute">
      <parent>base_link</parent>
      <child>waterprop_back_link</child>
      <axis>
        <xyz>1 0 0</xyz>
        <limit>
          <lower>-1000000</lower>
          <upper>1000000</upper>
          <effort>10</effort>
          <velocity>1000</velocity>
        </limit>
        <dynamics>
          <damping>0.001</damping>
          <friction>0.0</friction>
        </dynamics>
      </axis>
    </joint>

    <plugin
      filename="gz-sim-joint-trajectory-controller-system"
      name="gz::sim::systems::JointTrajectoryController">
      <topic>arm_trajectory</topic>
      <joint_name>arm_left_joint</joint_name>
      <initial_position>0.0</initial_position>
      <position_p_gain>5.0</position_p_gain>
      <position_i_gain>0.1</position_i_gain>
      <position_d_gain>0.01</position_d_gain>
      <position_i_min>-1</position_i_min>
      <position_i_max>1</position_i_max>
      <position_cmd_min>-10</position_cmd_min>
      <position_cmd_max>10</position_cmd_max>

      <joint_name>arm_right_joint</joint_name>
      <initial_position>0.0</initial_position>
      <position_p_gain>5.0</position_p_gain>
      <position_i_gain>0.1</position_i_gain>
      <position_d_gain>0.01</position_d_gain>
      <position_i_min>-1</position_i_min>
      <position_i_max>1</position_i_max>
      <position_cmd_min>-10</position_cmd_min>
      <position_cmd_max>10</position_cmd_max>
    </plugin>

    <plugin
      filename="gz-sim-joint-state-publisher-system"
      name="gz::sim::systems::JointStatePublisher">
      <joint_name>arm_left_joint</joint_name>
      <joint_name>arm_right_joint</joint_name>
    </plugin>

    <plugin filename="gz-sim-multicopter-motor-model-system" name="gz::sim::systems::MulticopterMotorModel">
      <jointName>airprop_rightfront_joint</jointName>
      <linkName>airprop_rightfront_link</linkName>
      <turningDirection>ccw</turningDirection>
      <timeConstantUp>0.015</timeConstantUp>
      <timeConstantDown>0.03</timeConstantDown>
      <maxRotVelocity>1585</maxRotVelocity>
      <motorConstant>1.64e-05</motorConstant>
      <momentConstant>0.018</momentConstant>
      <commandSubTopic>command/motor_speed</commandSubTopic>
      <motorNumber>0</motorNumber>
      <rotorDragCoefficient>0.0001</rotorDragCoefficient>
      <rollingMomentCoefficient>1e-06</rollingMomentCoefficient>
      <motorType>velocity</motorType>
    </plugin>

    <plugin filename="gz-sim-multicopter-motor-model-system" name="gz::sim::systems::MulticopterMotorModel">
      <jointName>airprop_leftfront_joint</jointName>
      <linkName>airprop_leftfront_link</linkName>
      <turningDirection>cw</turningDirection>
      <timeConstantUp>0.015</timeConstantUp>
      <timeConstantDown>0.03</timeConstantDown>
      <maxRotVelocity>1585</maxRotVelocity>
      <motorConstant>1.64e-05</motorConstant>
      <momentConstant>0.018</momentConstant>
      <commandSubTopic>command/motor_speed</commandSubTopic>
      <motorNumber>1</motorNumber>
      <rotorDragCoefficient>0.0001</rotorDragCoefficient>
      <rollingMomentCoefficient>1e-06</rollingMomentCoefficient>
      <motorType>velocity</motorType>
    </plugin>

    <plugin filename="gz-sim-multicopter-motor-model-system" name="gz::sim::systems::MulticopterMotorModel">
      <jointName>airprop_leftback_joint</jointName>
      <linkName>airprop_leftback_link</linkName>
      <turningDirection>ccw</turningDirection>
      <timeConstantUp>0.015</timeConstantUp>
      <timeConstantDown>0.03</timeConstantDown>
      <maxRotVelocity>1585</maxRotVelocity>
      <motorConstant>1.64e-05</motorConstant>
      <momentConstant>0.018</momentConstant>
      <commandSubTopic>command/motor_speed</commandSubTopic>
      <motorNumber>2</motorNumber>
      <rotorDragCoefficient>0.0001</rotorDragCoefficient>
      <rollingMomentCoefficient>1e-06</rollingMomentCoefficient>
      <motorType>velocity</motorType>
    </plugin>

    <plugin filename="gz-sim-multicopter-motor-model-system" name="gz::sim::systems::MulticopterMotorModel">
      <jointName>airprop_rightback_joint</jointName>
      <linkName>airprop_rightback_link</linkName>
      <turningDirection>cw</turningDirection>
      <timeConstantUp>0.015</timeConstantUp>
      <timeConstantDown>0.03</timeConstantDown>
      <maxRotVelocity>1585</maxRotVelocity>
      <motorConstant>1.64e-05</motorConstant>
      <momentConstant>0.018</momentConstant>
      <commandSubTopic>command/motor_speed</commandSubTopic>
      <motorNumber>3</motorNumber>
      <rotorDragCoefficient>0.0001</rotorDragCoefficient>
      <rollingMomentCoefficient>1e-06</rollingMomentCoefficient>
      <motorType>velocity</motorType>
    </plugin>

    <plugin filename="gz-sim-bidir-motor-model-system" name="gz::sim::v8::systems::BiDirectionalMotorModel">
      <jointName>waterprop_right_joint</jointName>
      <linkName>waterprop_right_link</linkName>
      <turningDirection>ccw</turningDirection>
      <timeConstantUp>0.0125</timeConstantUp>
      <timeConstantDown>0.025</timeConstantDown>
      <motorConstant>9.6065e-07</motorConstant>
      <momentConstant>-3.318e-10</momentConstant>
      <commandSubTopic>servo_0</commandSubTopic>
      <motorNumber>0</motorNumber>
      <thrustAxis>1 0 0</thrustAxis>
      <commandGain>57.29</commandGain>
      <deadbandOmega>10</deadbandOmega>
      <maxOmega>3500</maxOmega>
      <maxThrust>15</maxThrust>
      <maxTorque>1.5</maxTorque>
      <forwardCoeff>1.0</forwardCoeff>
      <reverseCoeff>0.86</reverseCoeff>
      <surface_z>0.0</surface_z>
      <transition_band>0.08</transition_band>
      <fluid_density_water>1000.0</fluid_density_water>
      <fluid_density_air>1.225</fluid_density_air>
      <sample_point>0 0 0</sample_point>
      <sample_point>0 0.018 0</sample_point>
      <sample_point>0 -0.018 0</sample_point>
      <sample_point>0 0 0.018</sample_point>
      <sample_point>0 0 -0.018</sample_point>
    </plugin>

    <plugin filename="gz-sim-bidir-motor-model-system" name="gz::sim::v8::systems::BiDirectionalMotorModel">
      <jointName>waterprop_front_joint</jointName>
      <linkName>waterprop_front_link</linkName>
      <turningDirection>ccw</turningDirection>
      <timeConstantUp>0.0125</timeConstantUp>
      <timeConstantDown>0.025</timeConstantDown>
      <motorConstant>9.6065e-07</motorConstant>
      <momentConstant>-3.318e-10</momentConstant>
      <commandSubTopic>servo_1</commandSubTopic>
      <motorNumber>0</motorNumber>
      <thrustAxis>1 0 0</thrustAxis>
      <commandGain>57.29</commandGain>
      <deadbandOmega>10</deadbandOmega>
      <maxOmega>3500</maxOmega>
      <maxThrust>15</maxThrust> 
      <maxTorque>1.5</maxTorque>
      <forwardCoeff>1.0</forwardCoeff>
      <reverseCoeff>0.86</reverseCoeff>
      <surface_z>0.0</surface_z>
      <transition_band>0.08</transition_band>
      <fluid_density_water>1000.0</fluid_density_water>
      <fluid_density_air>1.225</fluid_density_air>
      <sample_point>0 0 0</sample_point>
      <sample_point>0 0.018 0</sample_point>
      <sample_point>0 -0.018 0</sample_point>
      <sample_point>0 0 0.018</sample_point>
      <sample_point>0 0 -0.018</sample_point>
    </plugin>

    <plugin filename="gz-sim-bidir-motor-model-system" name="gz::sim::v8::systems::BiDirectionalMotorModel">
      <jointName>waterprop_left_joint</jointName>
      <linkName>waterprop_left_link</linkName>
      <turningDirection>ccw</turningDirection>
      <timeConstantUp>0.0125</timeConstantUp>
      <timeConstantDown>0.025</timeConstantDown>
      <motorConstant>9.6065e-07</motorConstant>
      <momentConstant>-3.318e-10</momentConstant>
      <commandSubTopic>servo_2</commandSubTopic>
      <motorNumber>0</motorNumber>
      <thrustAxis>1 0 0</thrustAxis>
      <commandGain>57.29</commandGain>
      <deadbandOmega>10</deadbandOmega>
      <maxOmega>3500</maxOmega>
      <maxThrust>15</maxThrust>
      <maxTorque>1.5</maxTorque>
      <forwardCoeff>1.0</forwardCoeff>
      <reverseCoeff>0.86</reverseCoeff>

    </plugin>

    <plugin filename="gz-sim-bidir-motor-model-system" name="gz::sim::v8::systems::BiDirectionalMotorModel">
      <jointName>waterprop_back_joint</jointName>
      <linkName>waterprop_back_link</linkName>
      <turningDirection>ccw</turningDirection>
      <timeConstantUp>0.0125</timeConstantUp>
      <timeConstantDown>0.025</timeConstantDown>
      <motorConstant>9.6065e-07</motorConstant>
      <momentConstant>-3.318e-10</momentConstant>
      <commandSubTopic>servo_3</commandSubTopic>
      <motorNumber>0</motorNumber>
      <thrustAxis>1 0 0</thrustAxis>
      <commandGain>57.29</commandGain>
      <deadbandOmega>10</deadbandOmega>
      <maxOmega>3500</maxOmega>
      <maxThrust>15</maxThrust>
      <maxTorque>1.5</maxTorque>
      <forwardCoeff>1.0</forwardCoeff>
      <reverseCoeff>0.86</reverseCoeff>
      <surface_z>0.0</surface_z>
      <transition_band>0.08</transition_band>
      <fluid_density_water>1000.0</fluid_density_water>
      <fluid_density_air>1.225</fluid_density_air>
    </plugin>

    <plugin filename="/home/user/external/plugins/hydrodynamics/build/libhydrodynamics.so" name="zyshine3_gz_plugins::HybridHydrodynamics">
      <hydrodynamics>
        <link_name>base_link</link_name>
        <surface_z>0.0</surface_z>
        <transition_band>0.1</transition_band>
        <fluid_density_water>1000.0</fluid_density_water>
        <fluid_density_air>1.225</fluid_density_air>
        <default_current>0 0 0</default_current>
        <air_clearance_margin>-0.02</air_clearance_margin>
        <!-- 浸沒比例采样点可以进一步优化 -->
        <sample_point>0.16 0.0 0.06</sample_point>
        <sample_point>0.16 0.0 -0.02</sample_point>
        <sample_point>0.06 0.12 0.05</sample_point>
        <sample_point>0.06 -0.12 0.05</sample_point>
        <sample_point>0.00 0.0 0.08</sample_point>
        <sample_point>0.00 0.0 -0.04</sample_point>
        <sample_point>-0.10 0.12 0.04</sample_point>
        <sample_point>-0.10 -0.12 0.04</sample_point>
        <sample_point>-0.14 0.0 -0.01</sample_point>

        <water_thruster_link_name>waterprop_right_link</water_thruster_link_name>
        <water_thruster_link_name>waterprop_front_link</water_thruster_link_name>
        <water_thruster_link_name>waterprop_left_link</water_thruster_link_name>
        <water_thruster_link_name>waterprop_back_link</water_thruster_link_name>

        <air_prop_link_name>airprop_rightfront_link</air_prop_link_name>
        <air_prop_link_name>airprop_leftfront_link</air_prop_link_name>
        <air_prop_link_name>airprop_leftback_link</air_prop_link_name>
        <air_prop_link_name>airprop_rightback_link</air_prop_link_name>

        <!-- HybridHydrodynamics v2 ：插件侧附加质量与附加质量科氏项。
             这里沿用传统水动力学导数符号约定，内部会按正幅值使用。 -->
        <enable_added_mass>true</enable_added_mass>
        <enable_added_mass_coriolis>true</enable_added_mass_coriolis>
        <xDotU>-0.01</xDotU>
        <yDotV>-0.02</yDotV>
        <zDotW>-0.01</zDotW>
        <kDotP>-0.08</kDotP>
        <mDotQ>-0.04</mDotQ>
        <nDotR>-0.02</nDotR>

        <!-- HybridHydrodynamics v2 新增：加速度估计滤波、限幅与 jerk 限制。
             这些是首版稳定性占位参数，后续可以结合日志继续调参。 -->
        <added_mass_velocity_filter_tau>0.03</added_mass_velocity_filter_tau>
        <added_mass_accel_filter_tau>0.06</added_mass_accel_filter_tau>
        <added_mass_linear_accel_limit>4.0</added_mass_linear_accel_limit>
        <added_mass_angular_accel_limit>8.0</added_mass_angular_accel_limit>
        <added_mass_linear_jerk_limit>20.0</added_mass_linear_jerk_limit>
        <added_mass_angular_jerk_limit>40.0</added_mass_angular_jerk_limit>
        <added_mass_reset_scale_threshold>0.05</added_mass_reset_scale_threshold>

        <!-- HybridHydrodynamics v2 阻尼参数：仍保留线性项与 abs 二次项。 -->
        <xU>-12.0</xU>
        <xUabsU>-15.0</xUabsU>
        <yV>-25.0</yV>
        <yVabsV>-65.0</yVabsV>
        <zW>-25.0</zW>
        <zWabsW>-42.0</zWabsW>
        <kP>-5.2</kP>
        <kPabsP>-1.5</kPabsP>
        <mQ>-5.0</mQ>
        <mQabsQ>-9.0</mQabsQ>
        <nR>-4.5</nR>
        <nRabsR>-10.5</nRabsR>
      </hydrodynamics>
    </plugin>

    <plugin filename="gz-sim-pose-publisher-system" name="gz::sim::systems::PosePublisher">
      <publish_link_pose>false</publish_link_pose>
      <publish_nested_model_pose>true</publish_nested_model_pose> 
      <publish_model_pose>true</publish_model_pose>
    </plugin>

  </model>
</sdf>
